Workbook
Name Slicer_Date_of_Match: #N/A

Sheet Sheet2
A4: Row Labels | B4: Sum of First Innings Score | C4: Sum of Second Innings Score
A5: Arnos Vale Ground
A6: Kingstown | B6: 643 | C6: 565
A7: Brian Lara Stadium
A8: Tarouba | B8: 418 | C8: 417
A9: Central Broward Regional Park Stadium Turf Ground
A10: Lauderhill | B10: 106 | C10: 111
A11: Daren Sammy National Cricket Stadium
A12: Gros Islet | B12: 1147 | C12: 936
A13: Grand Prairie Stadium
A14: Dallas | B14: 583 | C14: 591
A15: Kensington Oval
A16: Bridgetown | B16: 1319 | C16: 1106
A17: Nassau County International Cricket Stadium
A18: New York | B18: 861 | C18: 848
A19: Providence Stadium
A20: Providence | B20: 869 | C20: 490
A21: Sir Vivian Richards Stadium
A22: North Sound | B22: 1056 | C22: 907
A23: Grand Total | B23: 7002 | C23: 5971

Sheet ICC Mens T20 Worldcup
A1: Match No. | B1: Date of Match | C1: Venue Stadium | D1: Venue City | E1: 1st Team | F1: 2nd Team | G1: Stage | H1: Umpire 1 | I1: Umpire 2 | J1: Reserve Umpire | K1: Match Referee | L1: TV Umpire | M1: Toss Winning | N1: Toss Loser | O1: Toss Decision | P1: Match Result | Q1: First Innings Score | R1: Fall of wickets First Innings | S1: Second Innings Score | T1: Fall of wickets Second Innings | U1: Winners | V1: Losers | W1: Method | X1: Won by | Y1: Winning Margin | Z1: Top Run Scorer | AA1: Highest Score | AB1: Best Bowler | AC1: Best Bowler Figure(Wickets Taken) | AD1: Best Bowler Figure(Runs Recieved) | AE1: Player Of The Match | AF1: Super Over Match
A2: 1st | B2: 45328 | C2: Grand Prairie Stadium | D2: Dallas | E2: Canada | F2: United State Of America | G2: Group A | H2: Richard Illingworth | I2: Sharfuddoula | J2: Langton Rusere | K2: Richie Richardson | L2: Sam Nogajski | M2: United State Of America | N2: Canada | O2: Fielding | P2: Played | Q2: 194 | R2: 5 | S2: 197 | T2: 3 | U2: United State Of America | V2: Canada | W2: Normal Match | X2: Wickets | Y2: 7 | Z2: Aaron Jones | AA2: 94 | AB2: Dilon Heyliger | AC2: 1 | AD2: 19 | AE2: Aaron Jones | AF2: No
A3: 2nd | B3: 45328 | C3: Providence Stadium | D3: Providence | E3: Papua New Guinea | F3: West Indies | G3: Group C | H3: Adrian Holdstock | I3: Rashid Riaz | J3: Kumar Dharmasena | K3: Andy Pycroft | L3: Ahsan Raza | M3: West Indies | N3: Papua New Guinea | O3: Fielding | P3: Played | Q3: 136 | R3: 8 | S3: 137 | T3: 5 | U3: West Indies | V3: Papua New Guinea | W3: Normal Match | X3: Wickets | Y3: 5 | Z3: Sese Bau | AA3: 50 | AB3: Andre Russell | AC3: 2 | AD3: 19 | AE3: Roston Chase | AF3: No
A4: 3rd | B4: 45357 | C4: Kensington Oval | D4: Bridgetown | E4: Oman | F4: Namibia | G4: Group B | H4: Jayaraman Madanagopal | I4: Joel Wilson | J4: Asif Yaqoob | K4: Ranjan Madugalle | L4: Nitin Menon | M4: Namibia | N4: Oman | O4: Fielding | P4: Played | Q4: 109 | R4: 10 | S4: 109 | T4: 6 | U4: Namibia | V4: Oman | W4: Normal Match | X4: Wickets | Y4: 4 | Z4: Jan Frylinck | AA4: 45 | AB4: Mehran Khan | AC4: 3 | AD4: 7 | AE4: David Wiese | AF4: Yes
A5: 4th | B5: 45357 | C5: Nassau County International Cricket Stadium | D5: New York | E5: Sri Lanka | F5: South Africa | G5: Group D | H5: Chris Brown | I5: Richard Kettleborough | J5: Alex Wharf | K5: Jeff Crowe | L5: Paul Reiffel | M5: Sri Lanka | N5: South Africa | O5: Batting | P5: Played | Q5: 77 | R5: 10 | S5: 80 | T5: 4 | U5: South Africa | V5: Sri Lanka | W5: Normal Match | X5: Wickets | Y5: 6 | Z5: Quinton de Kock | AA5: 20 | AB5: Anrich Nortje | AC5: 4 | AD5: 7 | AE5: Anrich Nortje | AF5: No
A6: 5th | B6: 45388 | C6: Providence Stadium | D6: Providence | E6: Afghanistan | F6: Uganda | G6: Group C | H6: Ahsan Raza | I6: Kumar Dharmasena | J6: Rashid Riaz | K6: Andy Pycroft | L6: Adrian Holdstock | M6: Uganda | N6: Afghanistan | O6: Fielding | P6: Played | Q6: 183 | R6: 5 | S6: 58 | T6: 10 | U6: Afghanistan | V6: Uganda | W6: Normal Match | X6: Runs | Y6: 125 | Z6: Rahmanullah Gurbaz | AA6: 76 | AB6: Fazalhaq Farooqi | AC6: 5 | AD6: 9 | AE6: Fazalhaq Farooqi | AF6: No
A7: 6th | B7: 45418 | C7: Kensington Oval | D7: Bridgetown | E7: Scotland | F7: England | G7: Group B | H7: Asif Yaqoob | I7: Nitin Menon | J7: Jayaraman Madanagopal | K7: Ranjan Madugalle | L7: Joel Wilson | M7: Scotland | N7: England | O7: Batting | P7: Abandoned | Q7: 90 | R7: 0 | S7: 0 | T7: 0 | U7: No Result (Rain) | V7: No Result (Rain) | W7: No Result (Rain) | X7: No Result (Rain) | Y7: 0 | Z7: No Result (Rain) | AA7: 0 | AB7: No Result (Rain) | AC7: 0 | AD7: 0 | AE7: No Result (Rain) | AF7: No Result (Rain)
A8: 7th | B8: 45418 | C8: Grand Prairie Stadium | D8: Dallas | E8: Nepal | F8: Netherlands | G8: Group D | H8: Langton Rusere | I8: Rod Tucker | J8: Richard Illingworth | K8: Richie Richardson | L8: Sharfuddoula | M8: Netherlands | N8: Nepal | O8: Fielding | P8: Played | Q8: 106 | R8: 10 | S8: 109 | T8: 4 | U8: Netherlands | V8: Nepal | W8: Normal Match | X8: Wickets | Y8: 6 | Z8: Max O'Dowd | AA8: 54 | AB8: Tim Pringle | AC8: 3 | AD8: 20 | AE8: Tim Pringle | AF8: No
A9: 8th | B9: 45418 | C9: Nassau County International Cricket Stadium | D9: New York | E9: Ireland | F9: India | G9: Group A | H9: Alex Wharf | I9: Chris Gaffaney | J9: Chris Brown | K9: David Boon | L9: Richard Kettleborough | M9: India | N9: Ireland | O9: Fielding | P9: Played | Q9: 96 | R9: 10 | S9: 97 | T9: 2 | U9: India | V9: Ireland | W9: Normal Match | X9: Wickets | Y9: 8 | Z9: Rohit Sharma | AA9: 52 | AB9: Jasprit Bumrah | AC9: 2 | AD9: 6 | AE9: Jasprit Bumrah | AF9: No
A10: 9th | B10: 45449 | C10: Providence Stadium | D10: Providence | E10: Papua New Guinea | F10: Uganda | G10: Group C | H10: Adrian Holdstock | I10: Rashid Riaz | J10: Kumar Dharmasena | K10: Javagal Srinath | L10: Ahsan Raza | M10: Uganda | N10: Papua New Guinea | O10: Fielding | P10: Played | Q10: 77 | R10: 10 | S10: 78 | T10: 8 | U10: Uganda | V10: Papua New Guinea | W10: Normal Match | X10: Wickets | Y10: 3 | Z10: Riazat Ali Shah | AA10: 33 | AB10: Frank Nsubuga | AC10: 2 | AD10: 4 | AE10: Riazat Ali Shah | AF10: No
A11: 10th | B11: 45449 | C11: Kensington Oval | D11: Bridgetown | E11: Australia | F11: Oman | G11: Group B | H11: Asif Yaqoob | I11: Joel Wilson | J11: Nitin Menon | K11: Ranjan Madugalle | L11: Jayaraman Madanagopal | M11: Oman | N11: Australia | O11: Fielding | P11: Played | Q11: 164 | R11: 5 | S11: 125 | T11: 9 | U11: Australia | V11: Oman | W11: Normal Match | X11: Runs | Y11: 39 | Z11: Marcus Stoinis | AA11: 67 | AB11: Marcus Stoinis | AC11: 3 | AD11: 19 | AE11: Marcus Stoinis | AF11: No
A12: 11th | B12: 45479 | C12: Grand Prairie Stadium | D12: Dallas | E12: Pakistan | F12: United State Of America | G12: Group A | H12: Allahuddien Paleker | I12: Michael Gough | J12: Rod Tucker | K12: Jeff Crowe | L12: Paul Reiffel | M12: United State Of America | N12: Pakistan | O12: Fielding | P12: Played | Q12: 159 | R12: 7 | S12: 160 | T12: 3 | U12: United State Of America | V12: Pakistan | W12: Normal Match | X12: Runs | Y12: 1 | Z12: Monank Patel | AA12: 50 | AB12: Nosthush Kenjige | AC12: 3 | AD12: 30 | AE12: Monank Patel | AF12: Yes
A13: 12th | B13: 45479 | C13: Kensington Oval | D13: Bridgetown | E13: Namibia | F13: Scotland | G13: Group B | H13: Jayaraman Madanagopal | I13: Nitin Menon | J13: Joel Wilson | K13: Andy Pycroft | L13: Asif Yaqoob | M13: Namibia | N13: Scotland | O13: Batting | P13: Played | Q13: 155 | R13: 9 | S13: 157 | T13: 5 | U13: Scotland | V13: Namibia | W13: Normal Match | X13: Wickets | Y13: 5 | Z13: Michael Leask | AA13: 35 | AB13: Brad Currie | AC13: 2 | AD13: 16 | AE13: Michael Leask | AF13: No
... A26: 25th | B26: 45632 | C26: Nassau County International Cricket Stadium | D26: New York | E26: United State Of America | F26: India | G26: Group A | H26: Paul Reiffel | I26: Sam Nogajski | J26: Adrian Holdstock | K26: Ranjan Madugalle | L26: Kumar Dharmasena | M26: India | N26: United State Of America | O26: Fielding | P26: Played | Q26: 110 | R26: 8 | S26: 111 | T26: 3 | U26: India | V26: United State Of America | W26: Normal Match | X26: Wickets | Y26: 7 | Z26: Suryakumar Yadav | AA26: 50 | AB26: Arshdeep Singh | AC26: 4 | AD26: 9 | AE26: Arshdeep Singh | AF26: No
A27: 26th | B27: 13-06-2024 | C27: Brian Lara Stadium | D27: Tarouba | E27: West Indies | F27: New Zealand | G27: Group C | H27: Ahsan Raza | I27: Alex Wharf | J27: Michael Gough | K27: David Boon | L27: Richard Illingworth | M27: New Zealand | N27: West Indies | O27: Fielding | P27: Played | Q27: 149 | R27: 9 | S27: 136 | T27: 9 | U27: West Indies | V27: New Zealand | W27: Normal Match | X27: Runs | Y27: 13 | Z27: Sherfane Rutherford | AA27: 68 | AB27: Trent Boult | AC27: 3 | AD27: 16 | AE27: Sherfane Rutherford | AF27: No
A28: 27th | B28: 13-06-2024 | C28: Arnos Vale Ground | D28: Kingstown | E28: Bangladesh | F28: Netherlands | G28: Group D | H28: Chris Brown | I28: Jayaraman Madanagopal | J28: Joel Wilson | K28: Richie Richardson | L28: Allahuddien Paleker | M28: Netherlands | N28: Bangladesh | O28: Fielding | P28: Played | Q28: 159 | R28: 5 | S28: 134 | T28: 8 | U28: Bangladesh | V28: Netherlands | W28: Normal Match | X28: Runs | Y28: 25 | Z28: Shakib Al Hasan | AA28: 64 | AB28: Paul van Meekeren | AC28: 2 | AD28: 15 | AE28: Shakib Al Hasan | AF28: No
A29: 28th | B29: 14-06-2024 | C29: Sir Vivian Richards Stadium | D29: North Sound | E29: Oman | F29: England | G29: Group B | H29: Asif Yaqoob | I29: Langton Rusere | J29: Rashid Riaz | K29: Andy Pycroft | L29: Nitin Menon | M29: England | N29: Oman | O29: Fielding | P29: Played | Q29: 47 | R29: 10 | S29: 50 | T29: 2 | U29: England | V29: Oman | W29: Normal Match | X29: Wickets | Y29: 8 | Z29: Jos Buttler | AA29: 24 | AB29: Adil Rashid | AC29: 4 | AD29: 11 | AE29: Adil Rashid | AF29: No
A30: 29th | B30: 14-06-2024 | C30: Brian Lara Stadium | D30: Tarouba | E30: Papua New Guinea | F30: Afghanistan | G30: Group C | H30: Alex Wharf | I30: Michael Gough | J30: Ahsan Raza | K30: David Boon | L30: Richard Illingworth | M30: Afghanistan | N30: Papua New Guinea | O30: Fielding | P30: Played | Q30: 95 | R30: 10 | S30: 101 | T30: 3 | U30: Afghanistan | V30: Papua New Guinea | W30: Normal Match | X30: Wickets | Y30: 7 | Z30: Gulbadin Naib | AA30: 49 | AB30: Fazalhaq Farooqi | AC30: 3 | AD30: 16 | AE30: Fazalhaq Farooqi | AF30: No
A31: 30th | B31: 15-06-2024 | C31: Central Broward Regional Park Stadium Turf Ground | D31: Lauderhill | E31: United State Of America | F31: Ireland | G31: Group A | H31: Rod Tucker | I31: Sharfuddoula | J31: Richard Kettleborough | K31: Javagal Srinath | L31: Chris Gaffaney | M31: No Result (Rain) | N31: No Result (Rain) | O31: No Result (Rain) | P31: Abandoned | Q31: 0 | R31: 0 | S31: 0 | T31: 0 | U31: No Result (Rain) | V31: No Result (Rain) | W31: No Result (Rain) | X31: No Result (Rain) | Y31: 0 | Z31: No Result (Rain) | AA31: 0 | AB31: No Result (Rain) | AC31: 0 | AD31: 0 | AE31: No Result (Rain) | AF31: No Result (Rain)
A32: 31th | B32: 15-06-2024 | C32: Arnos Vale Ground | D32: Kingstown | E32: South Africa | F32: Nepal | G32: Group D | H32: Jayaraman Madanagopal | I32: Joel Wilson | J32: Sam Nogajski | K32: Richie Richardson | L32: Chris Brown | M32: Nepal | N32: South Africa | O32: Fielding | P32: Played | Q32: 115 | R32: 7 | S32: 114 | T32: 7 | U32: South Africa | V32: Nepal | W32: Normal Match | X32: Runs | Y32: 1 | Z32: Reeza Hendricks | AA32: 43 | AB32: Tabraiz Shamsi | AC32: 4 | AD32: 19 | AE32: Tabraiz Shamsi | AF32: No
A33: 32th | B33: 15-06-2024 | C33: Brian Lara Stadium | D33: Tarouba | E33: Uganda | F33: New Zealand | G33: Group C | H33: Paul Reiffel | I33: Richard Illingworth | J33: Ahsan Raza | K33: David Boon | L33: Kumar Dharmasena | M33: New Zealand | N33: Uganda | O33: Fielding | P33: Played | Q33: 40 | R33: 10 | S33: 41 | T33: 1 | U33: New Zealand | V33: Uganda | W33: Normal Match | X33: Wickets | Y33: 9 | Z33: Devon Conway | AA33: 22 | AB33: Tim Southee | AC33: 3 | AD33: 4 | AE33: Tim Southee | AF33: No
A34: 33th | B34: 16-06-2024 | C34: Central Broward Regional Park Stadium Turf Ground | D34: Lauderhill | E34: Canada | F34: India | G34: Group A | H34: Richard Kettleborough | I34: Sharfuddoula | J34: Chris Gaffaney | K34: Andy Pycroft | L34: Rod Tucker | M34: No Result (Rain) | N34: No Result (Rain) | O34: No Result (Rain) | P34: Abandoned | Q34: 0 | R34: 0 | S34: 0 | T34: 0 | U34: No Result (Rain) | V34: No Result (Rain) | W34: No Result (Rain) | X34: No Result (Rain) | Y34: 0 | Z34: No Result (Rain) | AA34: 0 | AB34: No Result (Rain) | AC34: 0 | AD34: 0 | AE34: No Result (Rain) | AF34: No Result (Rain)
A35: 34th | B35: 16-06-2024 | C35: Sir Vivian Richards Stadium | D35: North Sound | E35: England | F35: Namibia | G35: Group B | H35: Adrian Holdstock | I35: Langton Rusere | J35: Nitin Menon | K35: Ranjan Madugalle | L35: Rashid Riaz | M35: Namibia | N35: England | O35: Fielding | P35: Played | Q35: 122 | R35: 5 | S35: 84 | T35: 3 | U35: England | V35: Namibia | W35: Normal Match | X35: Runs | Y35: 41 | Z35: Harry Brook | AA35: 47 | AB35: David Wiese | AC35: 1 | AD35: 6 | AE35: Harry Brook | AF35: No
A36: 35th | B36: 16-06-2024 | C36: Daren Sammy National Cricket Stadium | D36: Gros Islet | E36: Scotland | F36: Australia | G36: Group B | H36: Asif Yaqoob | I36: Michael Gough | J36: Allahuddien Paleker | K36: Jeff Crowe | L36: Alex Wharf | M36: Australia | N36: Scotland | O36: Fielding | P36: Played | Q36: 180 | R36: 5 | S36: 186 | T36: 5 | U36: Australia | V36: Scotland | W36: Normal Match | X36: Wickets | Y36: 5 | Z36: Marcus Stoinis | AA36: 59 | AB36: Mark Watt | AC36: 2 | AD36: 34 | AE36: Marcus Stoinis | AF36: No
A37: 36th | B37: 16-06-2024 | C37: Central Broward Regional Park Stadium Turf Ground | D37: Lauderhill | E37: Ireland | F37: Pakistan | G37: Group A | H37: Chris Gaffaney | I37: Rod Tucker | J37: Richard Kettleborough | K37: Javagal Srinath | L37: Sharfuddoula | M37: Pakistan | N37: Ireland | O37: Fielding | P37: Played | Q37: 106 | R37: 9 | S37: 111 | T37: 7 | U37: Pakistan | V37: Ireland | W37: Normal Match | X37: Wickets | Y37: 3 | Z37: Babar Azam | AA37: 32 | AB37: Shaheen Shah Afridi | AC37: 3 | AD37: 22 | AE37: Shaheen Shah Afridi | AF37: No
A38: 37th | B38: 17-06-2024 | C38: Arnos Vale Ground | D38: Kingstown | E38: Bangladesh | F38: Nepal | G38: Group D | H38: Ahsan Raza | I38: Sam Nogajski | J38: Kumar Dharmasena | K38: Richie Richardson | L38: Jayaraman Madanagopal | M38: Nepal | N38: Bangladesh | O38: Fielding | P38: Played | Q38: 106 | R38: 10 | S38: 85 | T38: 10 | U38: Bangladesh | V38: Nepal | W38: Normal Match | X38: Runs | Y38: 21 | Z38: Kushal Malla | AA38: 27 | AB38: Tanzim Hasan Sakib | AC38: 4 | AD38: 7 | AE38: Tanzim Hasan Sakib | AF38: No
... A56: 55th | B56: 29-06-2024 | C56: Kensington Oval | D56: Bridgetown | E56: India | F56: South Africa | G56: Final | H56: Chris Gaffaney | I56: Richard Illingworth | J56: Rod Tucker | K56: Richie Richardson | L56: Richard Kettleborough | M56: India | N56: South Africa | O56: Batting | P56: Played | Q56: 176 | R56: 7 | S56: 169 | T56: 8 | U56: India | V56: South Africa | W56: Normal Match | X56: Runs | Y56: 7 | Z56: Virat Kohli | AA56: 76 | AB56: Hardik Pandya | AC56: 3 | AD56: 20 | AE56: Virat Kohli | AF56: No
Q58: =AVERAGE(Q2:Q56) -> 127.30909 | R58: =AVERAGE(R2:R56) -> 6.9818182 | S58: =AVERAGE(S1:S56) -> 108.56364 | T58: =AVERAGE(T2:T56) -> 5.3818182

Sheet Dashboard
B4: Toss & Match Win | C4: 1st ing score Avg | D4: 2nd Ing score Avg | E4: 1st ing avg wickets | F4: 2nd ing avg wickets | G4: Count True | H4: Count False | I4: Count Toss win and Fielding Choose | J4: Count Toss win and Batting Choose
A6: 1 | B6: =('ICC Mens T20 Worldcup'!M2)=('ICC Mens T20 Worldcup'!U2) -> TRUE | C6: ='ICC Mens T20 Worldcup'!Q58 -> 127.30909 | D6: ='ICC Mens T20 Worldcup'!S58 -> 108.56364 | E6: ='ICC Mens T20 Worldcup'!R58 -> 6.9818182 | F6: ='ICC Mens T20 Worldcup'!T58 -> 5.3818182 | G6: =COUNTIF(B6:B61,F12) -> 32 | H6: =COUNTIF(B6:B61,G12) -> 24 | I6: =COUNTIF('ICC Mens T20 Worldcup'!O2:O56,Dashboard!D13) -> 10 | J6: =COUNTIF('ICC Mens T20 Worldcup'!O2:O56,Dashboard!D14) -> 42
A7: 2 | B7: =('ICC Mens T20 Worldcup'!M3)=('ICC Mens T20 Worldcup'!U3) -> TRUE
A8: 3 | B8: =('ICC Mens T20 Worldcup'!M4)=('ICC Mens T20 Worldcup'!U4) -> TRUE
A9: 4 | B9: =('ICC Mens T20 Worldcup'!M5)=('ICC Mens T20 Worldcup'!U5) -> FALSE
A10: 5 | B10: =('ICC Mens T20 Worldcup'!M6)=('ICC Mens T20 Worldcup'!U6) -> FALSE
A11: 6 | B11: =('ICC Mens T20 Worldcup'!M7)=('ICC Mens T20 Worldcup'!U7) -> FALSE
A12: 7 | B12: =('ICC Mens T20 Worldcup'!M8)=('ICC Mens T20 Worldcup'!U8) -> TRUE | D12: Toss Decision | E12: Toss & matchs | F12: TRUE | G12: FALSE
A13: 8 | B13: =('ICC Mens T20 Worldcup'!M9)=('ICC Mens T20 Worldcup'!U9) -> TRUE | D13: Batting | E13: Toss Win & Matchs Win
A14: 9 | B14: =('ICC Mens T20 Worldcup'!M10)=('ICC Mens T20 Worldcup'!U10) -> TRUE | D14: Fielding | E14: Toss Win & Match Loss
A15: 10 | B15: =('ICC Mens T20 Worldcup'!M11)=('ICC Mens T20 Worldcup'!U11) -> FALSE | F15: Column1
A16: 11 | B16: =('ICC Mens T20 Worldcup'!M12)=('ICC Mens T20 Worldcup'!U12) -> TRUE
A17: 12 | B17: =('ICC Mens T20 Worldcup'!M13)=('ICC Mens T20 Worldcup'!U13) -> FALSE
A18: 13 | B18: =('ICC Mens T20 Worldcup'!M14)=('ICC Mens T20 Worldcup'!U14) -> FALSE
A19: 14 | B19: =('ICC Mens T20 Worldcup'!M15)=('ICC Mens T20 Worldcup'!U15) -> FALSE | D19: Venue Stadium | E19: First match score | F19: Matchs Played | G19: Avg 1st ing score | H19: Avg 2nd ing score | I19: Avg 1st ing Wickets | J19: Avg 1st ing Wickets
A20: 15 | B20: =('ICC Mens T20 Worldcup'!M16)=('ICC Mens T20 Worldcup'!U16) -> TRUE | C20: 1 | D20: ='ICC Mens T20 Worldcup'!C2 -> Grand Prairie Stadium | E20: =_xlfn.XLOOKUP(D20,'ICC Mens T20 Worldcup'!C2:C56,'ICC Mens T20 Worldcup'!Q2:Q56) -> 194 | F20: =COUNTIF('ICC Mens T20 Worldcup'!C2:C56,Dashboard!D20) -> 4 | G20: =AVERAGEIF('ICC Mens T20 Worldcup'!C2:C56,Dashboard!D20,'ICC Mens T20 Worldcup'!Q2:Q56) -> 145.75 | H20: =AVERAGEIF('ICC Mens T20 Worldcup'!C2:C56,Dashboard!D20,'ICC Mens T20 Worldcup'!S2:S56) -> 147.75 | I20: =AVERAGEIF('ICC Mens T20 Worldcup'!C2:C56,Dashboard!D20,'ICC Mens T20 Worldcup'!R2:R56) -> 7.75 | J20: =AVERAGEIF('ICC Mens T20 Worldcup'!C2:C56,Dashboard!D20,'ICC Mens T20 Worldcup'!T2:T56) -> 4.5
A21: 16 | B21: =('ICC Mens T20 Worldcup'!M17)=('ICC Mens T20 Worldcup'!U17) -> TRUE | C21: 2 | D21: ='ICC Mens T20 Worldcup'!C3 -> Providence Stadium | E21: =_xlfn.XLOOKUP(D21,'ICC Mens T20 Worldcup'!C3:C57,'ICC Mens T20 Worldcup'!Q3:Q57) -> 136 | F21: =COUNTIF('ICC Mens T20 Worldcup'!C3:C57,Dashboard!D21) -> 6 | G21: =AVERAGEIF('ICC Mens T20 Worldcup'!C3:C57,Dashboard!D21,'ICC Mens T20 Worldcup'!Q3:Q57) -> 144.83333 | H21: =AVERAGEIF('ICC Mens T20 Worldcup'!C3:C57,Dashboard!D21,'ICC Mens T20 Worldcup'!S3:S57) -> 81.666667 | I21: =AVERAGEIF('ICC Mens T20 Worldcup'!C3:C57,Dashboard!D21,'ICC Mens T20 Worldcup'!R3:R57) -> 6.8333333 | J21: =AVERAGEIF('ICC Mens T20 Worldcup'!C3:C57,Dashboard!D21,'ICC Mens T20 Worldcup'!T3:T57) -> 8.8333333
A22: 17 | B22: =('ICC Mens T20 Worldcup'!M18)=('ICC Mens T20 Worldcup'!U18) -> FALSE | C22: 3 | D22: ='ICC Mens T20 Worldcup'!C4 -> Kensington Oval | E22: =_xlfn.XLOOKUP(D22,'ICC Mens T20 Worldcup'!C4:C58,'ICC Mens T20 Worldcup'!Q4:Q58) -> 109 | F22: =COUNTIF('ICC Mens T20 Worldcup'!C4:C58,Dashboard!D22) -> 9 | G22: =AVERAGEIF('ICC Mens T20 Worldcup'!C4:C58,Dashboard!D22,'ICC Mens T20 Worldcup'!Q4:Q58) -> 146.55556 | H22: =AVERAGEIF('ICC Mens T20 Worldcup'!C4:C58,Dashboard!D22,'ICC Mens T20 Worldcup'!S4:S58) -> 122.88889 | I22: =AVERAGEIF('ICC Mens T20 Worldcup'!C4:C58,Dashboard!D22,'ICC Mens T20 Worldcup'!R4:R58) -> 7.3333333 | J22: =AVERAGEIF('ICC Mens T20 Worldcup'!C4:C58,Dashboard!D22,'ICC Mens T20 Worldcup'!T4:T58) -> 5
A23: 18 | B23: =('ICC Mens T20 Worldcup'!M19)=('ICC Mens T20 Worldcup'!U19) -> TRUE | C23: 4 | D23: ='ICC Mens T20 Worldcup'!C5 -> Nassau County International Cricket Stadium | E23: =_xlfn.XLOOKUP(D23,'ICC Mens T20 Worldcup'!C5:C59,'ICC Mens T20 Worldcup'!Q5:Q59) -> 77 | F23: =COUNTIF('ICC Mens T20 Worldcup'!C5:C59,Dashboard!D23) -> 8 | G23: =AVERAGEIF('ICC Mens T20 Worldcup'!C5:C59,Dashboard!D23,'ICC Mens T20 Worldcup'!Q5:Q59) -> 107.625 | H23: =AVERAGEIF('ICC Mens T20 Worldcup'!C5:C59,Dashboard!D23,'ICC Mens T20 Worldcup'!S5:S59) -> 106 | I23: =AVERAGEIF('ICC Mens T20 Worldcup'!C5:C59,Dashboard!D23,'ICC Mens T20 Worldcup'!R5:R59) -> 8.375 | J23: =AVERAGEIF('ICC Mens T20 Worldcup'!C5:C59,Dashboard!D23,'ICC Mens T20 Worldcup'!T5:T59) -> 4.875
A24: 19 | B24: =('ICC Mens T20 Worldcup'!M20)=('ICC Mens T20 Worldcup'!U20) -> FALSE | C24: 5 | D24: ='ICC Mens T20 Worldcup'!C21 -> Sir Vivian Richards Stadium | E24: =_xlfn.XLOOKUP(D24,'ICC Mens T20 Worldcup'!C6:C60,'ICC Mens T20 Worldcup'!Q6:Q60) -> 150 | F24: =COUNTIF('ICC Mens T20 Worldcup'!C6:C60,Dashboard!D24) -> 8 | G24: =AVERAGEIF('ICC Mens T20 Worldcup'!C6:C60,Dashboard!D24,'ICC Mens T20 Worldcup'!Q6:Q60) -> 132 | H24: =AVERAGEIF('ICC Mens T20 Worldcup'!C6:C60,Dashboard!D24,'ICC Mens T20 Worldcup'!S6:S60) -> 113.375 | I24: =AVERAGEIF('ICC Mens T20 Worldcup'!C6:C60,Dashboard!D24,'ICC Mens T20 Worldcup'!R6:R60) -> 7.125 | J24: =AVERAGEIF('ICC Mens T20 Worldcup'!C6:C60,Dashboard!D24,'ICC Mens T20 Worldcup'!T6:T60) -> 4
A25: 20 | B25: =('ICC Mens T20 Worldcup'!M21)=('ICC Mens T20 Worldcup'!U21) -> FALSE | C25: 6 | D25: ='ICC Mens T20 Worldcup'!C24 -> Central Broward Regional Park Stadium Turf Ground | E25: =_xlfn.XLOOKUP(D25,'ICC Mens T20 Worldcup'!C7:C61,'ICC Mens T20 Worldcup'!Q7:Q61) -> 0 | F25: =COUNTIF('ICC Mens T20 Worldcup'!C7:C61,Dashboard!D25) -> 4 | G25: =AVERAGEIF('ICC Mens T20 Worldcup'!C7:C61,Dashboard!D25,'ICC Mens T20 Worldcup'!Q7:Q61) -> 26.5 | H25: =AVERAGEIF('ICC Mens T20 Worldcup'!C7:C61,Dashboard!D25,'ICC Mens T20 Worldcup'!S7:S61) -> 27.75 | I25: =AVERAGEIF('ICC Mens T20 Worldcup'!C7:C61,Dashboard!D25,'ICC Mens T20 Worldcup'!R7:R61) -> 2.25 | J25: =AVERAGEIF('ICC Mens T20 Worldcup'!C7:C61,Dashboard!D25,'ICC Mens T20 Worldcup'!T7:T61) -> 1.75
A26: 21 | B26: =('ICC Mens T20 Worldcup'!M22)=('ICC Mens T20 Worldcup'!U22) -> TRUE | C26: 7 | D26: ='ICC Mens T20 Worldcup'!C27 -> Brian Lara Stadium | E26: =_xlfn.XLOOKUP(D26,'ICC Mens T20 Worldcup'!C8:C62,'ICC Mens T20 Worldcup'!Q8:Q62) -> 149 | F26: =COUNTIF('ICC Mens T20 Worldcup'!C8:C62,Dashboard!D26) -> 5 | G26: =AVERAGEIF('ICC Mens T20 Worldcup'!C8:C62,Dashboard!D26,'ICC Mens T20 Worldcup'!Q8:Q62) -> 83.6 | H26: =AVERAGEIF('ICC Mens T20 Worldcup'!C8:C62,Dashboard!D26,'ICC Mens T20 Worldcup'!S8:S62) -> 83.4 | I26: =AVERAGEIF('ICC Mens T20 Worldcup'!C8:C62,Dashboard!D26,'ICC Mens T20 Worldcup'!R8:R62) -> 9.8 | J26: =AVERAGEIF('ICC Mens T20 Worldcup'!C8:C62,Dashboard!D26,'ICC Mens T20 Worldcup'!T8:T62) -> 3.4
A27: 22 | B27: =('ICC Mens T20 Worldcup'!M23)=('ICC Mens T20 Worldcup'!U23) -> TRUE | C27: 8 | D27: ='ICC Mens T20 Worldcup'!C28 -> Arnos Vale Ground | E27: =_xlfn.XLOOKUP(D27,'ICC Mens T20 Worldcup'!C9:C63,'ICC Mens T20 Worldcup'!Q9:Q63) -> 159 | F27: =COUNTIF('ICC Mens T20 Worldcup'!C9:C63,Dashboard!D27) -> 5 | G27: =AVERAGEIF('ICC Mens T20 Worldcup'!C9:C63,Dashboard!D27,'ICC Mens T20 Worldcup'!Q9:Q63) -> 128.6 | H27: =AVERAGEIF('ICC Mens T20 Worldcup'!C9:C63,Dashboard!D27,'ICC Mens T20 Worldcup'!S9:S63) -> 113 | I27: =AVERAGEIF('ICC Mens T20 Worldcup'!C9:C63,Dashboard!D27,'ICC Mens T20 Worldcup'!R9:R63) -> 6.6 | J27: =AVERAGEIF('ICC Mens T20 Worldcup'!C9:C63,Dashboard!D27,'ICC Mens T20 Worldcup'!T9:T63) -> 9
A28: 23 | B28: =('ICC Mens T20 Worldcup'!M24)=('ICC Mens T20 Worldcup'!U24) -> TRUE | C28: 9 | D28: ='ICC Mens T20 Worldcup'!C36 -> Daren Sammy National Cricket Stadium | E28: =_xlfn.XLOOKUP(D28,'ICC Mens T20 Worldcup'!C10:C64,'ICC Mens T20 Worldcup'!Q10:Q64) -> 180 | F28: =COUNTIF('ICC Mens T20 Worldcup'!C10:C64,Dashboard!D28) -> 6 | G28: =AVERAGEIF('ICC Mens T20 Worldcup'!C10:C64,Dashboard!D28,'ICC Mens T20 Worldcup'!Q10:Q64) -> 191.16667 | H28: =AVERAGEIF('ICC Mens T20 Worldcup'!C10:C64,Dashboard!D28,'ICC Mens T20 Worldcup'!S10:S64) -> 156 | I28: =AVERAGEIF('ICC Mens T20 Worldcup'!C10:C64,Dashboard!D28,'ICC Mens T20 Worldcup'!R10:R64) -> 5.1666667 | J28: =AVERAGEIF('ICC Mens T20 Worldcup'!C10:C64,Dashboard!D28,'ICC Mens T20 Worldcup'!T10:T64) -> 6.6666667
A29: 24 | B29: =('ICC Mens T20 Worldcup'!M25)=('ICC Mens T20 Worldcup'!U25) -> TRUE
A30: 25 | B30: =('ICC Mens T20 Worldcup'!M26)=('ICC Mens T20 Worldcup'!U26) -> TRUE | F30: =SUM(F20:F29) -> 55 | G30: =AVERAGE(G20:G28) -> 122.95895 | H30: =AVERAGE(H20:H28) -> 105.75895 | I30: =AVERAGE(I20:I28) -> 6.8037037 | J30: =AVERAGE(J20:J28) -> 5.3361111
A31: 26 | B31: =('ICC Mens T20 Worldcup'!M27)=('ICC Mens T20 Worldcup'!U27) -> FALSE
A32: 27 | B32: =('ICC Mens T20 Worldcup'!M28)=('ICC Mens T20 Worldcup'!U28) -> FALSE
A33: 28 | B33: =('ICC Mens T20 Worldcup'!M29)=('ICC Mens T20 Worldcup'!U29) -> TRUE
A34: 29 | B34: =('ICC Mens T20 Worldcup'!M30)=('ICC Mens T20 Worldcup'!U30) -> TRUE
A35: 30 | B35: =('ICC Mens T20 Worldcup'!M31)=('ICC Mens T20 Worldcup'!U31) -> TRUE
A36: 31 | B36: =('ICC Mens T20 Worldcup'!M32)=('ICC Mens T20 Worldcup'!U32) -> FALSE
A37: 32 | B37: =('ICC Mens T20 Worldcup'!M33)=('ICC Mens T20 Worldcup'!U33) -> TRUE
A38: 33 | B38: =('ICC Mens T20 Worldcup'!M34)=('ICC Mens T20 Worldcup'!U34) -> TRUE
A39: 34 | B39: =('ICC Mens T20 Worldcup'!M35)=('ICC Mens T20 Worldcup'!U35) -> FALSE
A40: 35 | B40: =('ICC Mens T20 Worldcup'!M36)=('ICC Mens T20 Worldcup'!U36) -> TRUE
A41: 36 | B41: =('ICC Mens T20 Worldcup'!M37)=('ICC Mens T20 Worldcup'!U37) -> TRUE
A42: 37 | B42: =('ICC Mens T20 Worldcup'!M38)=('ICC Mens T20 Worldcup'!U38) -> FALSE
... A59: 54 | B59: =('ICC Mens T20 Worldcup'!M55)=('ICC Mens T20 Worldcup'!U55) -> FALSE
A60: 55 | B60: =('ICC Mens T20 Worldcup'!M56)=('ICC Mens T20 Worldcup'!U56) -> TRUE | D60: ='ICC Mens T20 Worldcup'!H1 -> Umpire 1 | E60: ='ICC Mens T20 Worldcup'!I1 -> Umpire 2 | F60: ='ICC Mens T20 Worldcup'!J1 -> Reserve Umpire | G60: ='ICC Mens T20 Worldcup'!K1 -> Match Referee | H60: ='ICC Mens T20 Worldcup'!L1 -> TV Umpire | I60: No
...
